Workbook
Name Slicer_Country: #N/A

Sheet marketing_campaign_dataset_500_
A1: Campaign_ID | B1: Date | C1: Customer_ID | D1: Age | E1: Gender | F1: Country | G1: Marketing_Channel | H1: Campaign_Type | I1: Ad_Spend | J1: Impressions | K1: Clicks | L1: Conversions | M1: Customer_Satisfaction | N1: CTR_% | O1: Conversion_Rate_% | P1: Cust_satifaction_full | S1: avg_cust_satisfaction | U1: Num_over_100 | V1: Perfomance_Rating | W1: CTR_Category | X1: Spend_Flag | Y1: Channel_Benchmark | Z1: Performance_vs_Benchmark | AA1: Campaign_type_flag
A2: MKT1000 | B2: 45467 | C2: C378 | D2: 27 | E2: Male | F2: USA | G2: Facebook Ads | H2: Product Launch | I2: 1779.52 | J2: 35715 | K2: 3140 | L2: 274 | M2: 2 | N2: 8.7918242 | O2: 8.7261146 | P2: =IF(ISBLANK(M2), $S$2, M2) -> 2 | S2: =ROUND(AVERAGE(M:M),0) -> 3 | U2: =COUNTIF(N2:N1000, N2>100) -> 0 | V2: =IF(AND(L2>200,K2>3000),"Top Performer", IF(AND(L2>=100,K2>=1000),"Average Performer","Low Performer")) -> Top Performer | W2: {=_xlfn.IFS(N2>=20, "High",N2>=10, "Medium", N2<10, "Low")} -> Low | X2: =IF(I2>1000, "High Budget",IF(I2>=500, "Medium Budget", "Low Budget")) -> High Budget | Y2: =VLOOKUP(G2, Lookup_table!B:C,2,0) -> 0.5 | Z2: =IF(I2/K2<Y2, "Efficient Spend", "Inefficient Spend") -> Inefficient Spend | AA2: =VLOOKUP(H2, Lookup_table!E:F,2,0) -> High
A3: MKT1001 | B3: 45488 | C3: C345 | D3: 24 | E3: Female | F3: Nigeria | G3: Google Ads | H3: Brand Awareness | I3: 464.78 | J3: 13758 | K3: 3324 | L3: 5 | M3: 3 | N3: 24.160488 | O3: 0.15042118 | P3: =IF(ISBLANK(M3), $S$2, M3) -> 3 | U3: =COUNTIF(N3:N1001, N3>100) -> 0 | V3: =IF(AND(L3>200,K3>3000),"Top Performer", IF(AND(L3>=100,K3>=1000),"Average Performer","Low Performer")) -> Low Performer | W3: {=_xlfn.IFS(N3>=20, "High",N3>=10, "Medium", N3<10, "Low")} -> High | X3: =IF(I3>1000, "High Budget",IF(I3>=500, "Medium Budget", "Low Budget")) -> Low Budget | Y3: =VLOOKUP(G3, Lookup_table!B:C,2,0) -> 1.2 | Z3: =IF(I3/K3<Y3, "Efficient Spend", "Inefficient Spend") -> Efficient Spend | AA3: =VLOOKUP(H3, Lookup_table!E:F,2,0) -> Medium
A4: MKT1002 | B4: 45317 | C4: C239 | D4: 35 | E4: Other | F4: USA | G4: Facebook Ads | H4: Holiday Promo | I4: 561.14 | J4: 48381 | K4: 321 | L4: 163 | N4: 0.6634836 | O4: 50.778816 | P4: =IF(ISBLANK(M4), $S$2, M4) -> 3 | V4: =IF(AND(L4>200,K4>3000),"Top Performer", IF(AND(L4>=100,K4>=1000),"Average Performer","Low Performer")) -> Low Performer | W4: {=_xlfn.IFS(N4>=20, "High",N4>=10, "Medium", N4<10, "Low")} -> Low | X4: =IF(I4>1000, "High Budget",IF(I4>=500, "Medium Budget", "Low Budget")) -> Medium Budget | Y4: =VLOOKUP(G4, Lookup_table!B:C,2,0) -> 0.5 | Z4: =IF(I4/K4<Y4, "Efficient Spend", "Inefficient Spend") -> Inefficient Spend | AA4: =VLOOKUP(H4, Lookup_table!E:F,2,0) -> High
A5: MKT1003 | B5: 45359 | C5: C266 | D5: 20 | E5: Male | F5: Nigeria | G5: Facebook Ads | H5: Brand Awareness | I5: 297.57 | J5: 15697 | K5: 3375 | L5: 280 | M5: 5 | N5: 21.500924 | O5: 8.2962963 | P5: =IF(ISBLANK(M5), $S$2, M5) -> 5 | U5: =COUNTIF(N5:N1000, N5>100) -> 0 | V5: =IF(AND(L5>200,K5>3000),"Top Performer", IF(AND(L5>=100,K5>=1000),"Average Performer","Low Performer")) -> Top Performer | W5: {=_xlfn.IFS(N5>=20, "High",N5>=10, "Medium", N5<10, "Low")} -> High | X5: =IF(I5>1000, "High Budget",IF(I5>=500, "Medium Budget", "Low Budget")) -> Low Budget | Y5: =VLOOKUP(G5, Lookup_table!B:C,2,0) -> 0.5 | Z5: =IF(I5/K5<Y5, "Efficient Spend", "Inefficient Spend") -> Efficient Spend | AA5: =VLOOKUP(H5, Lookup_table!E:F,2,0) -> Medium
A6: MKT1004 | B6: 45503 | C6: C282 | D6: 32 | E6: Female | F6: UK | G6: Referral | H6: Holiday Promo | I6: 1074.86 | J6: 2245 | K6: 4858 | L6: 373 | M6: 2 | N6: 216.39198 | O6: 7.6780568 | P6: =IF(ISBLANK(M6), $S$2, M6) -> 2 | U6: =COUNTIF(N6:N1001, N6>100) -> 0 | V6: =IF(AND(L6>200,K6>3000),"Top Performer", IF(AND(L6>=100,K6>=1000),"Average Performer","Low Performer")) -> Top Performer | W6: {=_xlfn.IFS(N6>=20, "High",N6>=10, "Medium", N6<10, "Low")} -> High | X6: =IF(I6>1000, "High Budget",IF(I6>=500, "Medium Budget", "Low Budget")) -> High Budget | Y6: =VLOOKUP(G6, Lookup_table!B:C,2,0) -> 0.3 | Z6: =IF(I6/K6<Y6, "Efficient Spend", "Inefficient Spend") -> Efficient Spend | AA6: =VLOOKUP(H6, Lookup_table!E:F,2,0) -> High
A7: MKT1005 | B7: 45395 | C7: C227 | D7: 64 | E7: Other | F7: Ghana | G7: Instagram | H7: Brand Awareness | I7: 665.19 | J7: 10209 | K7: 2859 | L7: 149 | M7: 5 | N7: 28.004702 | O7: 5.2116125 | P7: =IF(ISBLANK(M7), $S$2, M7) -> 5 | U7: =COUNTIF(N7:N1002, N7>100) -> 0 | V7: =IF(AND(L7>200,K7>3000),"Top Performer", IF(AND(L7>=100,K7>=1000),"Average Performer","Low Performer")) -> Average Performer | W7: {=_xlfn.IFS(N7>=20, "High",N7>=10, "Medium", N7<10, "Low")} -> High | X7: =IF(I7>1000, "High Budget",IF(I7>=500, "Medium Budget", "Low Budget")) -> Medium Budget | Y7: =VLOOKUP(G7, Lookup_table!B:C,2,0) -> 0.75 | Z7: =IF(I7/K7<Y7, "Efficient Spend", "Inefficient Spend") -> Efficient Spend | AA7: =VLOOKUP(H7, Lookup_table!E:F,2,0) -> Medium
A8: MKT1006 | B8: 45640 | C8: C279 | D8: 20 | E8: Other | F8: UK | G8: Instagram | H8: Holiday Promo | I8: 514.58 | J8: 11892 | K8: 367 | L8: 293 | M8: 4 | N8: 3.0861083 | O8: 79.836512 | P8: =IF(ISBLANK(M8), $S$2, M8) -> 4 | U8: =COUNTIF(N8:N1003, N8>100) -> 0 | V8: =IF(AND(L8>200,K8>3000),"Top Performer", IF(AND(L8>=100,K8>=1000),"Average Performer","Low Performer")) -> Low Performer | W8: {=_xlfn.IFS(N8>=20, "High",N8>=10, "Medium", N8<10, "Low")} -> Low | X8: =IF(I8>1000, "High Budget",IF(I8>=500, "Medium Budget", "Low Budget")) -> Medium Budget | Y8: =VLOOKUP(G8, Lookup_table!B:C,2,0) -> 0.75 | Z8: =IF(I8/K8<Y8, "Efficient Spend", "Inefficient Spend") -> Inefficient Spend | AA8: =VLOOKUP(H8, Lookup_table!E:F,2,0) -> High
A9: MKT1007 | B9: 45477 | C9: C279 | D9: 49 | E9: Other | F9: South Africa | G9: Referral | H9: Holiday Promo | I9: 187.7 | J9: 34575 | K9: 4519 | L9: 6 | M9: 3 | N9: 13.070137 | O9: 0.13277274 | P9: =IF(ISBLANK(M9), $S$2, M9) -> 3 | U9: =COUNTIF(N9:N1004, N9>100) -> 0 | V9: =IF(AND(L9>200,K9>3000),"Top Performer", IF(AND(L9>=100,K9>=1000),"Average Performer","Low Performer")) -> Low Performer | W9: {=_xlfn.IFS(N9>=20, "High",N9>=10, "Medium", N9<10, "Low")} -> Medium | X9: =IF(I9>1000, "High Budget",IF(I9>=500, "Medium Budget", "Low Budget")) -> Low Budget | Y9: =VLOOKUP(G9, Lookup_table!B:C,2,0) -> 0.3 | Z9: =IF(I9/K9<Y9, "Efficient Spend", "Inefficient Spend") -> Efficient Spend | AA9: =VLOOKUP(H9, Lookup_table!E:F,2,0) -> High
A10: MKT1008 | B10: 45315 | C10: C338 | D10: 26 | E10: Female | F10: South Africa | G10: Facebook Ads | H10: Product Launch | I10: 1985.97 | J10: 26045 | K10: 2084 | L10: 240 | M10: 4 | N10: 8.0015358 | O10: 11.516315 | P10: =IF(ISBLANK(M10), $S$2, M10) -> 4 | U10: =COUNTIF(N10:N1005, N10>100) -> 0 | V10: =IF(AND(L10>200,K10>3000),"Top Performer", IF(AND(L10>=100,K10>=1000),"Average Performer","Low Performer")) -> Average Performer | W10: {=_xlfn.IFS(N10>=20, "High",N10>=10, "Medium", N10<10, "Low")} -> Low | X10: =IF(I10>1000, "High Budget",IF(I10>=500, "Medium Budget", "Low Budget")) -> High Budget | Y10: =VLOOKUP(G10, Lookup_table!B:C,2,0) -> 0.5 | Z10: =IF(I10/K10<Y10, "Efficient Spend", "Inefficient Spend") -> Inefficient Spend | AA10: =VLOOKUP(H10, Lookup_table!E:F,2,0) -> High
A11: MKT1009 | B11: 45364 | C11: C346 | D11: 31 | E11: Other | F11: Nigeria | G11: Instagram | H11: Brand Awareness | I11: 1642.32 | J11: 8802 | K11: 735 | L11: 220 | M11: 5 | N11: 8.3503749 | O11: 29.931973 | P11: =IF(ISBLANK(M11), $S$2, M11) -> 5 | U11: =COUNTIF(N11:N1006, N11>100) -> 0 | V11: =IF(AND(L11>200,K11>3000),"Top Performer", IF(AND(L11>=100,K11>=1000),"Average Performer","Low Performer")) -> Low Performer | W11: {=_xlfn.IFS(N11>=20, "High",N11>=10, "Medium", N11<10, "Low")} -> Low | X11: =IF(I11>1000, "High Budget",IF(I11>=500, "Medium Budget", "Low Budget")) -> High Budget | Y11: =VLOOKUP(G11, Lookup_table!B:C,2,0) -> 0.75 | Z11: =IF(I11/K11<Y11, "Efficient Spend", "Inefficient Spend") -> Inefficient Spend | AA11: =VLOOKUP(H11, Lookup_table!E:F,2,0) -> Medium
A12: MKT1010 | B12: 45637 | C12: C252 | D12: 46 | E12: Male | F12: Kenya | G12: Referral | H12: Product Launch | I12: 686.5 | J12: 8134 | K12: 1108 | L12: 140 | M12: 1 | N12: 13.621834 | O12: 12.635379 | P12: =IF(ISBLANK(M12), $S$2, M12) -> 1 | U12: =COUNTIF(N12:N1007, N12>100) -> 0 | V12: =IF(AND(L12>200,K12>3000),"Top Performer", IF(AND(L12>=100,K12>=1000),"Average Performer","Low Performer")) -> Average Performer | W12: {=_xlfn.IFS(N12>=20, "High",N12>=10, "Medium", N12<10, "Low")} -> Medium | X12: =IF(I12>1000, "High Budget",IF(I12>=500, "Medium Budget", "Low Budget")) -> Medium Budget | Y12: =VLOOKUP(G12, Lookup_table!B:C,2,0) -> 0.3 | Z12: =IF(I12/K12<Y12, "Efficient Spend", "Inefficient Spend") -> Inefficient Spend | AA12: =VLOOKUP(H12, Lookup_table!E:F,2,0) -> High
A13: MKT1011 | B13: 45334 | C13: C334 | D13: 59 | E13: Other | F13: South Africa | G13: Google Ads | H13: Product Launch | I13: 847.08 | J13: 24160 | K13: 4205 | L13: 211 | M13: 5 | N13: 17.404801 | O13: 5.0178359 | P13: =IF(ISBLANK(M13), $S$2, M13) -> 5 | U13: =COUNTIF(N13:N1008, N13>100) -> 0 | V13: =IF(AND(L13>200,K13>3000),"Top Performer", IF(AND(L13>=100,K13>=1000),"Average Performer","Low Performer")) -> Top Performer | W13: {=_xlfn.IFS(N13>=20, "High",N13>=10, "Medium", N13<10, "Low")} -> Medium | X13: =IF(I13>1000, "High Budget",IF(I13>=500, "Medium Budget", "Low Budget")) -> Medium Budget | Y13: =VLOOKUP(G13, Lookup_table!B:C,2,0) -> 1.2 | Z13: =IF(I13/K13<Y13, "Efficient Spend", "Inefficient Spend") -> Efficient Spend | AA13: =VLOOKUP(H13, Lookup_table!E:F,2,0) -> High
A14: MKT1012 | B14: 45510 | C14: C345 | D14: 44 | E14: Other | F14: Nigeria | G14: Email | H14: Discount | I14: 1143.36 | J14: 8173 | K14: 825 | L14: 16 | N14: 10.094213 | O14: 1.9393939 | P14: =IF(ISBLANK(M14), $S$2, M14) -> 3 | U14: =COUNTIF(N14:N1009, N14>100) -> 0 | V14: =IF(AND(L14>200,K14>3000),"Top Performer", IF(AND(L14>=100,K14>=1000),"Average Performer","Low Performer")) -> Low Performer | W14: {=_xlfn.IFS(N14>=20, "High",N14>=10, "Medium", N14<10, "Low")} -> Medium | X14: =IF(I14>1000, "High Budget",IF(I14>=500, "Medium Budget", "Low Budget")) -> High Budget | Y14: =VLOOKUP(G14, Lookup_table!B:C,2,0) -> 0.2 | Z14: =IF(I14/K14<Y14, "Efficient Spend", "Inefficient Spend") -> Inefficient Spend | AA14: =VLOOKUP(H14, Lookup_table!E:F,2,0) -> Medium
A15: MKT1013 | B15: 45459 | C15: C267 | D15: 57 | E15: Male | F15: South Africa | G15: Facebook Ads | H15: Discount | I15: 151.38 | J15: 11942 | K15: 4640 | L15: 59 | M15: 3 | N15: 38.854463 | O15: 1.2715517 | P15: =IF(ISBLANK(M15), $S$2, M15) -> 3 | V15: =IF(AND(L15>200,K15>3000),"Top Performer", IF(AND(L15>=100,K15>=1000),"Average Performer","Low Performer")) -> Low Performer | W15: {=_xlfn.IFS(N15>=20, "High",N15>=10, "Medium", N15<10, "Low")} -> High | X15: =IF(I15>1000, "High Budget",IF(I15>=500, "Medium Budget", "Low Budget")) -> Low Budget | Y15: =VLOOKUP(G15, Lookup_table!B:C,2,0) -> 0.5 | Z15: =IF(I15/K15<Y15, "Efficient Spend", "Inefficient Spend") -> Efficient Spend | AA15: =VLOOKUP(H15, Lookup_table!E:F,2,0) -> Medium
A16: MKT1014 | B16: 45360 | C16: C290 | D16: 36 | E16: Female | F16: USA | G16: Facebook Ads | H16: Discount | I16: 782.56 | J16: 9132 | K16: 1618 | L16: 74 | M16: 1 | N16: 17.717915 | O16: 4.5735476 | P16: =IF(ISBLANK(M16), $S$2, M16) -> 1 | V16: =IF(AND(L16>200,K16>3000),"Top Performer", IF(AND(L16>=100,K16>=1000),"Average Performer","Low Performer")) -> Low Performer | W16: {=_xlfn.IFS(N16>=20, "High",N16>=10, "Medium", N16<10, "Low")} -> Medium | X16: =IF(I16>1000, "High Budget",IF(I16>=500, "Medium Budget", "Low Budget")) -> Medium Budget | Y16: =VLOOKUP(G16, Lookup_table!B:C,2,0) -> 0.5 | Z16: =IF(I16/K16<Y16, "Efficient Spend", "Inefficient Spend") -> Efficient Spend | AA16: =VLOOKUP(H16, Lookup_table!E:F,2,0) -> Medium
A17: MKT1015 | B17: 45292 | C17: C300 | D17: 38 | E17: Male | F17: Ghana | G17: Instagram | H17: Holiday Promo | I17: 1170.73 | J17: 45111 | K17: 602 | L17: 207 | M17: 1 | N17: 1.334486 | O17: 34.385382 | P17: =IF(ISBLANK(M17), $S$2, M17) -> 1 | V17: =IF(AND(L17>200,K17>3000),"Top Performer", IF(AND(L17>=100,K17>=1000),"Average Performer","Low Performer")) -> Low Performer | W17: {=_xlfn.IFS(N17>=20, "High",N17>=10, "Medium", N17<10, "Low")} -> Low | X17: =IF(I17>1000, "High Budget",IF(I17>=500, "Medium Budget", "Low Budget")) -> High Budget | Y17: =VLOOKUP(G17, Lookup_table!B:C,2,0) -> 0.75 | Z17: =IF(I17/K17<Y17, "Efficient Spend", "Inefficient Spend") -> Inefficient Spend | AA17: =VLOOKUP(H17, Lookup_table!E:F,2,0) -> High
A18: MKT1016 | B18: 45367 | C18: C300 | D18: 41 | E18: Male | F18: Kenya | G18: Referral | H18: Holiday Promo | I18: 1924.46 | J18: 5516 | K18: 4976 | L18: 221 | M18: 5 | N18: 90.210297 | O18: 4.4413183 | P18: =IF(ISBLANK(M18), $S$2, M18) -> 5 | V18: =IF(AND(L18>200,K18>3000),"Top Performer", IF(AND(L18>=100,K18>=1000),"Average Performer","Low Performer")) -> Top Performer | W18: {=_xlfn.IFS(N18>=20, "High",N18>=10, "Medium", N18<10, "Low")} -> High | X18: =IF(I18>1000, "High Budget",IF(I18>=500, "Medium Budget", "Low Budget")) -> High Budget | Y18: =VLOOKUP(G18, Lookup_table!B:C,2,0) -> 0.3 | Z18: =IF(I18/K18<Y18, "Efficient Spend", "Inefficient Spend") -> Inefficient Spend | AA18: =VLOOKUP(H18, Lookup_table!E:F,2,0) -> High
A19: MKT1017 | B19: 45603 | C19: C210 | D19: 46 | E19: Male | F19: South Africa | G19: Email | H19: Product Launch | I19: 1929.87 | J19: 9198 | K19: 497 | L19: 300 | M19: 5 | N19: 5.4033486 | O19: 60.362173 | P19: =IF(ISBLANK(M19), $S$2, M19) -> 5 | V19: =IF(AND(L19>200,K19>3000),"Top Performer", IF(AND(L19>=100,K19>=1000),"Average Performer","Low Performer")) -> Low Performer | W19: {=_xlfn.IFS(N19>=20, "High",N19>=10, "Medium", N19<10, "Low")} -> Low | X19: =IF(I19>1000, "High Budget",IF(I19>=500, "Medium Budget", "Low Budget")) -> High Budget | Y19: =VLOOKUP(G19, Lookup_table!B:C,2,0) -> 0.2 | Z19: =IF(I19/K19<Y19, "Efficient Spend", "Inefficient Spend") -> Inefficient Spend | AA19: =VLOOKUP(H19, Lookup_table!E:F,2,0) -> High
A20: MKT1018 | B20: 45542 | C20: C211 | D20: 46 | E20: Female | F20: Kenya | G20: Email | H20: Brand Awareness | I20: 1527.84 | J20: 13127 | K20: 4960 | L20: 351 | M20: 5 | N20: 37.784719 | O20: 7.0766129 | P20: =IF(ISBLANK(M20), $S$2, M20) -> 5 | V20: =IF(AND(L20>200,K20>3000),"Top Performer", IF(AND(L20>=100,K20>=1000),"Average Performer","Low Performer")) -> Top Performer | W20: {=_xlfn.IFS(N20>=20, "High",N20>=10, "Medium", N20<10, "Low")} -> High | X20: =IF(I20>1000, "High Budget",IF(I20>=500, "Medium Budget", "Low Budget")) -> High Budget | Y20: =VLOOKUP(G20, Lookup_table!B:C,2,0) -> 0.2 | Z20: =IF(I20/K20<Y20, "Efficient Spend", "Inefficient Spend") -> Inefficient Spend | AA20: =VLOOKUP(H20, Lookup_table!E:F,2,0) -> Medium
A21: MKT1019 | B21: 45298 | C21: C341 | D21: 33 | E21: Female | F21: South Africa | G21: Email | H21: Brand Awareness | I21: 149.18 | J21: 33722 | K21: 3046 | L21: 323 | M21: 4 | N21: 9.032679 | O21: 10.604071 | P21: =IF(ISBLANK(M21), $S$2, M21) -> 4 | V21: =IF(AND(L21>200,K21>3000),"Top Performer", IF(AND(L21>=100,K21>=1000),"Average Performer","Low Performer")) -> Top Performer | W21: {=_xlfn.IFS(N21>=20, "High",N21>=10, "Medium", N21<10, "Low")} -> Low | X21: =IF(I21>1000, "High Budget",IF(I21>=500, "Medium Budget", "Low Budget")) -> Low Budget | Y21: =VLOOKUP(G21, Lookup_table!B:C,2,0) -> 0.2 | Z21: =IF(I21/K21<Y21, "Efficient Spend", "Inefficient Spend") -> Efficient Spend | AA21: =VLOOKUP(H21, Lookup_table!E:F,2,0) -> Medium
A22: MKT1020 | B22: 45567 | C22: C359 | D22: 63 | E22: Other | F22: Kenya | G22: Instagram | H22: Holiday Promo | I22: 1226.99 | J22: 5271 | K22: 717 | L22: 289 | M22: 4 | N22: 13.602732 | O22: 40.306834 | P22: =IF(ISBLANK(M22), $S$2, M22) -> 4 | V22: =IF(AND(L22>200,K22>3000),"Top Performer", IF(AND(L22>=100,K22>=1000),"Average Performer","Low Performer")) -> Low Performer | W22: {=_xlfn.IFS(N22>=20, "High",N22>=10, "Medium", N22<10, "Low")} -> Medium | X22: =IF(I22>1000, "High Budget",IF(I22>=500, "Medium Budget", "Low Budget")) -> High Budget | Y22: =VLOOKUP(G22, Lookup_table!B:C,2,0) -> 0.75 | Z22: =IF(I22/K22<Y22, "Efficient Spend", "Inefficient Spend") -> Inefficient Spend | AA22: =VLOOKUP(H22, Lookup_table!E:F,2,0) -> High
A23: MKT1021 | B23: 45336 | C23: C298 | D23: 51 | E23: Female | F23: Ghana | G23: Google Ads | H23: Brand Awareness | I23: 948.77 | J23: 11269 | K23: 1703 | L23: 321 | M23: 2 | N23: 15.112255 | O23: 18.84909 | P23: =IF(ISBLANK(M23), $S$2, M23) -> 2 | V23: =IF(AND(L23>200,K23>3000),"Top Performer", IF(AND(L23>=100,K23>=1000),"Average Performer","Low Performer")) -> Average Performer | W23: {=_xlfn.IFS(N23>=20, "High",N23>=10, "Medium", N23<10, "Low")} -> Medium | X23: =IF(I23>1000, "High Budget",IF(I23>=500, "Medium Budget", "Low Budget")) -> Medium Budget | Y23: =VLOOKUP(G23, Lookup_table!B:C,2,0) -> 1.2 | Z23: =IF(I23/K23<Y23, "Efficient Spend", "Inefficient Spend") -> Efficient Spend | AA23: =VLOOKUP(H23, Lookup_table!E:F,2,0) -> Medium
A24: MKT1022 | B24: 45483 | C24: C367 | D24: 18 | E24: Female | F24: UK | G24: Email | H24: Discount | I24: 1314.42 | J24: 46761 | K24: 3166 | L24: 267 | M24: 4 | N24: 6.7705994 | O24: 8.4333544 | P24: =IF(ISBLANK(M24), $S$2, M24) -> 4 | V24: =IF(AND(L24>200,K24>3000),"Top Performer", IF(AND(L24>=100,K24>=1000),"Average Performer","Low Performer")) -> Top Performer | W24: {=_xlfn.IFS(N24>=20, "High",N24>=10, "Medium", N24<10, "Low")} -> Low | X24: =IF(I24>1000, "High Budget",IF(I24>=500, "Medium Budget", "Low Budget")) -> High Budget | Y24: =VLOOKUP(G24, Lookup_table!B:C,2,0) -> 0.2 | Z24: =IF(I24/K24<Y24, "Efficient Spend", "Inefficient Spend") -> Inefficient Spend | AA24: =VLOOKUP(H24, Lookup_table!E:F,2,0) -> Medium
A25: MKT1023 | B25: 45617 | C25: C363 | D25: 19 | E25: Male | F25: South Africa | G25: Google Ads | H25: Discount | I25: 820.68 | J25: 31180 | K25: 3849 | L25: 261 | M25: 3 | N25: 12.344452 | O25: 6.7809821 | P25: =IF(ISBLANK(M25), $S$2, M25) -> 3 | V25: =IF(AND(L25>200,K25>3000),"Top Performer", IF(AND(L25>=100,K25>=1000),"Average Performer","Low Performer")) -> Top Performer | W25: {=_xlfn.IFS(N25>=20, "High",N25>=10, "Medium", N25<10, "Low")} -> Medium | X25: =IF(I25>1000, "High Budget",IF(I25>=500, "Medium Budget", "Low Budget")) -> Medium Budget | Y25: =VLOOKUP(G25, Lookup_table!B:C,2,0) -> 1.2 | Z25: =IF(I25/K25<Y25, "Efficient Spend", "Inefficient Spend") -> Efficient Spend | AA25: =VLOOKUP(H25, Lookup_table!E:F,2,0) -> Medium
A26: MKT1024 | B26: 45604 | C26: C224 | D26: 42 | E26: Other | F26: UK | G26: Referral | H26: Discount | I26: 1019.29 | J26: 11855 | K26: 482 | L26: 113 | N26: 4.065795 | O26: 23.443983 | P26: =IF(ISBLANK(M26), $S$2, M26) -> 3 | V26: =IF(AND(L26>200,K26>3000),"Top Performer", IF(AND(L26>=100,K26>=1000),"Average Performer","Low Performer")) -> Low Performer | W26: {=_xlfn.IFS(N26>=20, "High",N26>=10, "Medium", N26<10, "Low")} -> Low | X26: =IF(I26>1000, "High Budget",IF(I26>=500, "Medium Budget", "Low Budget")) -> High Budget | Y26: =VLOOKUP(G26, Lookup_table!B:C,2,0) -> 0.3 | Z26: =IF(I26/K26<Y26, "Efficient Spend", "Inefficient Spend") -> Inefficient Spend | AA26: =VLOOKUP(H26, Lookup_table!E:F,2,0) -> Medium
A27: MKT1025 | B27: 45444 | C27: C338 | D27: 57 | E27: Female | F27: Ghana | G27: Instagram | H27: Holiday Promo | I27: 921.21 | J27: 33409 | K27: 3245 | L27: 6 | N27: 9.7129516 | O27: 0.18489985 | P27: =IF(ISBLANK(M27), $S$2, M27) -> 3 | V27: =IF(AND(L27>200,K27>3000),"Top Performer", IF(AND(L27>=100,K27>=1000),"Average Performer","Low Performer")) -> Low Performer | W27: {=_xlfn.IFS(N27>=20, "High",N27>=10, "Medium", N27<10, "Low")} -> Low | X27: =IF(I27>1000, "High Budget",IF(I27>=500, "Medium Budget", "Low Budget")) -> Medium Budget | Y27: =VLOOKUP(G27, Lookup_table!B:C,2,0) -> 0.75 | Z27: =IF(I27/K27<Y27, "Efficient Spend", "Inefficient Spend") -> Efficient Spend | AA27: =VLOOKUP(H27, Lookup_table!E:F,2,0) -> High
A28: MKT1026 | B28: 45475 | C28: C280 | D28: 54 | E28: Male | F28: Kenya | G28: Instagram | H28: Holiday Promo | I28: 312.38 | J28: 5193 | K28: 2334 | L28: 253 | M28: 2 | N28: 44.945118 | O28: 10.83976 | P28: =IF(ISBLANK(M28), $S$2, M28) -> 2 | V28: =IF(AND(L28>200,K28>3000),"Top Performer", IF(AND(L28>=100,K28>=1000),"Average Performer","Low Performer")) -> Average Performer | W28: {=_xlfn.IFS(N28>=20, "High",N28>=10, "Medium", N28<10, "Low")} -> High | X28: =IF(I28>1000, "High Budget",IF(I28>=500, "Medium Budget", "Low Budget")) -> Low Budget | Y28: =VLOOKUP(G28, Lookup_table!B:C,2,0) -> 0.75 | Z28: =IF(I28/K28<Y28, "Efficient Spend", "Inefficient Spend") -> Efficient Spend | AA28: =VLOOKUP(H28, Lookup_table!E:F,2,0) -> High
A29: MKT1027 | B29: 45404 | C29: C246 | E29: Female | G29: Google Ads | H29: Discount | I29: 1461.16 | J29: 29339 | K29: 2849 | L29: 67 | N29: 9.7106241 | O29: 2.3517024 | P29: =IF(ISBLANK(M29), $S$2, M29) -> 3 | V29: =IF(AND(L29>200,K29>3000),"Top Performer", IF(AND(L29>=100,K29>=1000),"Average Performer","Low Performer")) -> Low Performer | W29: {=_xlfn.IFS(N29>=20, "High",N29>=10, "Medium", N29<10, "Low")} -> Low | X29: =IF(I29>1000, "High Budget",IF(I29>=500, "Medium Budget", "Low Budget")) -> High Budget | Y29: =VLOOKUP(G29, Lookup_table!B:C,2,0) -> 1.2 | Z29: =IF(I29/K29<Y29, "Efficient Spend", "Inefficient Spend") -> Efficient Spend | AA29: =VLOOKUP(H29, Lookup_table!E:F,2,0) -> Medium
A30: MKT1028 | B30: 45543 | C30: C350 | D30: 40 | E30: Female | F30: USA | G30: Google Ads | H30: Discount | I30: 64.23 | J30: 14536 | K30: 2927 | L30: 375 | N30: 20.136214 | O30: 12.811753 | P30: =IF(ISBLANK(M30), $S$2, M30) -> 3 | V30: =IF(AND(L30>200,K30>3000),"Top Performer", IF(AND(L30>=100,K30>=1000),"Average Performer","Low Performer")) -> Average Performer | W30: {=_xlfn.IFS(N30>=20, "High",N30>=10, "Medium", N30<10, "Low")} -> High | X30: =IF(I30>1000, "High Budget",IF(I30>=500, "Medium Budget", "Low Budget")) -> Low Budget | Y30: =VLOOKUP(G30, Lookup_table!B:C,2,0) -> 1.2 | Z30: =IF(I30/K30<Y30, "Efficient Spend", "Inefficient Spend") -> Efficient Spend | AA30: =VLOOKUP(H30, Lookup_table!E:F,2,0) -> Medium
A31: MKT1029 | B31: 45481 | C31: C363 | D31: 61 | E31: Male | F31: USA | G31: Instagram | H31: Holiday Promo | I31: 987.76 | J31: 1245 | K31: 4323 | L31: 119 | M31: 5 | N31: 347.22892 | O31: 2.752718 | P31: =IF(ISBLANK(M31), $S$2, M31) -> 5 | U31: =COUNTIF(N27:N1000, N31>100) -> 0 | V31: =IF(AND(L31>200,K31>3000),"Top Performer", IF(AND(L31>=100,K31>=1000),"Average Performer","Low Performer")) -> Average Performer | W31: {=_xlfn.IFS(N31>=20, "High",N31>=10, "Medium", N31<10, "Low")} -> High | X31: =IF(I31>1000, "High Budget",IF(I31>=500, "Medium Budget", "Low Budget")) -> Medium Budget | Y31: =VLOOKUP(G31, Lookup_table!B:C,2,0) -> 0.75 | Z31: =IF(I31/K31<Y31, "Efficient Spend", "Inefficient Spend") -> Efficient Spend | AA31: =VLOOKUP(H31, Lookup_table!E:F,2,0) -> High
A32: MKT1030 | B32: 45582 | C32: C313 | D32: 19 | E32: Male | F32: Kenya | G32: Referral | H32: Product Launch | I32: 1670.14 | J32: 47856 | K32: 3265 | L32: 392 | M32: 3 | N32: 6.822551 | O32: 12.006126 | P32: =IF(ISBLANK(M32), $S$2, M32) -> 3 | V32: =IF(AND(L32>200,K32>3000),"Top Performer", IF(AND(L32>=100,K32>=1000),"Average Performer","Low Performer")) -> Top Performer | W32: {=_xlfn.IFS(N32>=20, "High",N32>=10, "Medium", N32<10, "Low")} -> Low | X32: =IF(I32>1000, "High Budget",IF(I32>=500, "Medium Budget", "Low Budget")) -> High Budget | Y32: =VLOOKUP(G32, Lookup_table!B:C,2,0) -> 0.3 | Z32: =IF(I32/K32<Y32, "Efficient Spend", "Inefficient Spend") -> Inefficient Spend | AA32: =VLOOKUP(H32, Lookup_table!E:F,2,0) -> High
A33: MKT1031 | B33: 45604 | C33: C207 | D33: 38 | E33: Male | F33: South Africa | G33: Facebook Ads | H33: Product Launch | I33: 1582.87 | J33: 18161 | K33: 3759 | L33: 384 | M33: 2 | N33: 20.698199 | O33: 10.215483 | P33: =IF(ISBLANK(M33), $S$2, M33) -> 2 | V33: =IF(AND(L33>200,K33>3000),"Top Performer", IF(AND(L33>=100,K33>=1000),"Average Performer","Low Performer")) -> Top Performer | W33: {=_xlfn.IFS(N33>=20, "High",N33>=10, "Medium", N33<10, "Low")} -> High | X33: =IF(I33>1000, "High Budget",IF(I33>=500, "Medium Budget", "Low Budget")) -> High Budget | Y33: =VLOOKUP(G33, Lookup_table!B:C,2,0) -> 0.5 | Z33: =IF(I33/K33<Y33, "Efficient Spend", "Inefficient Spend") -> Efficient Spend | AA33: =VLOOKUP(H33, Lookup_table!E:F,2,0) -> High
A34: MKT1032 | B34: 45493 | C34: C246 | D34: 26 | E34: Other | F34: USA | G34: Facebook Ads | H34: Holiday Promo | I34: 688.82 | J34: 44318 | K34: 2759 | L34: 389 | M34: 3 | N34: 6.2254614 | O34: 14.099311 | P34: =IF(ISBLANK(M34), $S$2, M34) -> 3 | V34: =IF(AND(L34>200,K34>3000),"Top Performer", IF(AND(L34>=100,K34>=1000),"Average Performer","Low Performer")) -> Average Performer | W34: {=_xlfn.IFS(N34>=20, "High",N34>=10, "Medium", N34<10, "Low")} -> Low | X34: =IF(I34>1000, "High Budget",IF(I34>=500, "Medium Budget", "Low Budget")) -> Medium Budget | Y34: =VLOOKUP(G34, Lookup_table!B:C,2,0) -> 0.5 | Z34: =IF(I34/K34<Y34, "Efficient Spend", "Inefficient Spend") -> Efficient Spend | AA34: =VLOOKUP(H34, Lookup_table!E:F,2,0) -> High
A35: MKT1033 | B35: 45330 | C35: C255 | D35: 41 | E35: Other | F35: Ghana | G35: Email | H35: Holiday Promo | I35: 1079.14 | J35: 48566 | K35: 610 | L35: 85 | N35: 1.2560227 | O35: 13.934426 | P35: =IF(ISBLANK(M35), $S$2, M35) -> 3 | V35: =IF(AND(L35>200,K35>3000),"Top Performer", IF(AND(L35>=100,K35>=1000),"Average Performer","Low Performer")) -> Low Performer | W35: {=_xlfn.IFS(N35>=20, "High",N35>=10, "Medium", N35<10, "Low")} -> #NAME? | X35: =IF(I35>1000, "High Budget",IF(I35>=500, "Medium Budget", "Low Budget")) -> High Budget | Y35: =VLOOKUP(G35, Lookup_table!B:C,2,0) -> 0.2 | Z35: =IF(I35/K35<Y35, "Efficient Spend", "Inefficient Spend") -> Inefficient Spend | AA35: =VLOOKUP(H35, Lookup_table!E:F,2,0) -> High
A36: MKT1034 | B36: 45552 | C36: C283 | D36: 64 | E36: Other | F36: South Africa | G36: Google Ads | H36: Brand Awareness | I36: 1823.94 | J36: 22377 | K36: 803 | L36: 72 | M36: 3 | N36: 3.5885061 | O36: 8.9663761 | P36: =IF(ISBLANK(M36), $S$2, M36) -> 3 | V36: =IF(AND(L36>200,K36>3000),"Top Performer", IF(AND(L36>=100,K36>=1000),"Average Performer","Low Performer")) -> Low Performer | W36: {=_xlfn.IFS(N36>=20, "High",N36>=10, "Medium", N36<10, "Low")} -> #NAME? | X36: =IF(I36>1000, "High Budget",IF(I36>=500, "Medium Budget", "Low Budget")) -> High Budget | Y36: =VLOOKUP(G36, Lookup_table!B:C,2,0) -> 1.2 | Z36: =IF(I36/K36<Y36, "Efficient Spend", "Inefficient Spend") -> Inefficient Spend | AA36: =VLOOKUP(H36, Lookup_table!E:F,2,0) -> Medium
A37: MKT1035 | B37: 45429 | C37: C334 | D37: 45 | E37: Male | F37: Ghana | G37: Email | H37: Brand Awareness | I37: 654.81 | J37: 38824 | K37: 1908 | L37: 68 | M37: 5 | N37: 4.9144859 | O37: 3.5639413 | P37: =IF(ISBLANK(M37), $S$2, M37) -> 5 | V37: =IF(AND(L37>200,K37>3000),"Top Performer", IF(AND(L37>=100,K37>=1000),"Average Performer","Low Performer")) -> Low Performer | W37: {=_xlfn.IFS(N37>=20, "High",N37>=10, "Medium", N37<10, "Low")} -> #NAME? | X37: =IF(I37>1000, "High Budget",IF(I37>=500, "Medium Budget", "Low Budget")) -> Medium Budget | Y37: =VLOOKUP(G37, Lookup_table!B:C,2,0) -> 0.2 | Z37: =IF(I37/K37<Y37, "Efficient Spend", "Inefficient Spend") -> Inefficient Spend | AA37: =VLOOKUP(H37, Lookup_table!E:F,2,0) -> Medium
A38: MKT1036 | B38: 45635 | C38: C288 | D38: 53 | E38: Other | F38: Nigeria | G38: Email | H38: Discount | I38: 1182.54 | J38: 26747 | K38: 100 | L38: 348 | M38: 4 | N38: 0.37387371 | O38: 348 | P38: =IF(ISBLANK(M38), $S$2, M38) -> 4 | V38: =IF(AND(L38>200,K38>3000),"Top Performer", IF(AND(L38>=100,K38>=1000),"Average Performer","Low Performer")) -> Low Performer | W38: {=_xlfn.IFS(N38>=20, "High",N38>=10, "Medium", N38<10, "Low")} -> #NAME? | X38: =IF(I38>1000, "High Budget",IF(I38>=500, "Medium Budget", "Low Budget")) -> High Budget | Y38: =VLOOKUP(G38, Lookup_table!B:C,2,0) -> 0.2 | Z38: =IF(I38/K38<Y38, "Efficient Spend", "Inefficient Spend") -> Inefficient Spend | AA38: =VLOOKUP(H38, Lookup_table!E:F,2,0) -> Medium
A39: MKT1037 | B39: 45487 | C39: C243 | E39: Other | G39: Facebook Ads | H39: Brand Awareness | I39: 1871.43 | J39: 43985 | K39: 2058 | L39: 237 | N39: 4.6788678 | O39: 11.516035 | P39: =IF(ISBLANK(M39), $S$2, M39) -> 3 | V39: =IF(AND(L39>200,K39>3000),"Top Performer", IF(AND(L39>=100,K39>=1000),"Average Performer","Low Performer")) -> Average Performer | W39: {=_xlfn.IFS(N39>=20, "High",N39>=10, "Medium", N39<10, "Low")} -> #NAME? | X39: =IF(I39>1000, "High Budget",IF(I39>=500, "Medium Budget", "Low Budget")) -> High Budget | Y39: =VLOOKUP(G39, Lookup_table!B:C,2,0) -> 0.5 | Z39: =IF(I39/K39<Y39, "Efficient Spend", "Inefficient Spend") -> Inefficient Spend | AA39: =VLOOKUP(H39, Lookup_table!E:F,2,0) -> Medium
A40: MKT1038 | B40: 45364 | C40: C263 | D40: 40 | E40: Female | F40: USA | G40: Google Ads | H40: Brand Awareness | I40: 1909.57 | J40: 38605 | K40: 1277 | L40: 345 | N40: 3.3078617 | O40: 27.016445 | P40: =IF(ISBLANK(M40), $S$2, M40) -> 3 | V40: =IF(AND(L40>200,K40>3000),"Top Performer", IF(AND(L40>=100,K40>=1000),"Average Performer","Low Performer")) -> Average Performer | W40: {=_xlfn.IFS(N40>=20, "High",N40>=10, "Medium", N40<10, "Low")} -> #NAME? | X40: =IF(I40>1000, "High Budget",IF(I40>=500, "Medium Budget", "Low Budget")) -> High Budget | Y40: =VLOOKUP(G40, Lookup_table!B:C,2,0) -> 1.2 | Z40: =IF(I40/K40<Y40, "Efficient Spend", "Inefficient Spend") -> Inefficient Spend | AA40: =VLOOKUP(H40, Lookup_table!E:F,2,0) -> Medium
...

Sheet Summary sheet
A1: Averages | B1: Values
A2: Customer satisfaction | B2: =AVERAGE([1]marketing_campaign_dataset_500_!M:M) -> #VALUE!

Sheet Lookup_table
A1: Channel_ID | B1: Maarketing_Channel | C1: CPC_Benchmark | E1: Campaign_type | F1: Priority
A2: CH001 | B2: Facebook Ads | C2: 0.5 | E2: Product Launch | F2: High
A3: CH002 | B3: Google Ads | C3: 1.2 | E3: Brand Awareness | F3: Medium
A4: CH003 | B4: Instagram | C4: 0.75 | E4: Holiday Promo | F4: High
A5: CH004 | B5: Referral | C5: 0.3 | E5: Seasonal Sale | F5: Medium
A6: CH005 | B6: Email | C6: 0.2 | E6: Other | F6: Low
E7: Discount | F7: Medium

Sheet Dynamic_report
A1: Marketing_Channel | B1: Total_Campaigns | C1: Total_Conversions | D1: Total_Ad-Spend | E1: Average_CTR | F1: Avg_Satisfaction
A2: Facebook Ads | B2: =COUNTIF(marketing_campaign_dataset_500_!G:G,A2) -> 101 | C2: =SUMIF(marketing_campaign_dataset_500_!G:G,A2,marketing_campaign_dataset_500_!L:L) -> 18835 | D2: =SUMIF(marketing_campaign_dataset_500_!G:G,A2,marketing_campaign_dataset_500_!I:I) -> 109367.46 | E2: =AVERAGEIF(marketing_campaign_dataset_500_!G:G,A2,marketing_campaign_dataset_500_!N:N) -> 17.592856 | F2: =IFERROR(AVERAGEIF(marketing_campaign_dataset_500_!G:G,A2,marketing_campaign_dataset_500_!P:P),0) -> 2.8514851
A3: Google Ads | B3: =COUNTIF(marketing_campaign_dataset_500_!G:G,A3) -> 101 | C3: =SUMIF(marketing_campaign_dataset_500_!G:G,A3,marketing_campaign_dataset_500_!L:L) -> 20533 | D3: =SUMIF(marketing_campaign_dataset_500_!G:G,A3,marketing_campaign_dataset_500_!I:I) -> 102540.65 | E3: =AVERAGEIF(marketing_campaign_dataset_500_!G:G,A3,marketing_campaign_dataset_500_!N:N) -> 32.836177 | F3: =IFERROR(AVERAGEIF(marketing_campaign_dataset_500_!G:G,A3,marketing_campaign_dataset_500_!P:P),0) -> 2.7623762
A4: Instagram | B4: =COUNTIF(marketing_campaign_dataset_500_!G:G,A4) -> 110 | C4: =SUMIF(marketing_campaign_dataset_500_!G:G,A4,marketing_campaign_dataset_500_!L:L) -> 22625 | D4: =SUMIF(marketing_campaign_dataset_500_!G:G,A4,marketing_campaign_dataset_500_!I:I) -> 114210.1 | E4: =AVERAGEIF(marketing_campaign_dataset_500_!G:G,A4,marketing_campaign_dataset_500_!N:N) -> 26.721513 | F4: =IFERROR(AVERAGEIF(marketing_campaign_dataset_500_!G:G,A4,marketing_campaign_dataset_500_!P:P),0) -> 3.3545455
A5: Referral | B5: =COUNTIF(marketing_campaign_dataset_500_!G:G,A5) -> 100 | C5: =SUMIF(marketing_campaign_dataset_500_!G:G,A5,marketing_campaign_dataset_500_!L:L) -> 20318 | D5: =SUMIF(marketing_campaign_dataset_500_!G:G,A5,marketing_campaign_dataset_500_!I:I) -> 106296.51 | E5: =AVERAGEIF(marketing_campaign_dataset_500_!G:G,A5,marketing_campaign_dataset_500_!N:N) -> 25.13039 | F5: =IFERROR(AVERAGEIF(marketing_campaign_dataset_500_!G:G,A5,marketing_campaign_dataset_500_!P:P),0) -> 3.09
A6: Email | B6: =COUNTIF(marketing_campaign_dataset_500_!G:G,A6) -> 88 | C6: =SUMIF(marketing_campaign_dataset_500_!G:G,A6,marketing_campaign_dataset_500_!L:L) -> 15640 | D6: =SUMIF(marketing_campaign_dataset_500_!G:G,A6,marketing_campaign_dataset_500_!I:I) -> 86773.24 | E6: =AVERAGEIF(marketing_campaign_dataset_500_!G:G,A6,marketing_campaign_dataset_500_!N:N) -> 29.815668 | F6: =IFERROR(AVERAGEIF(marketing_campaign_dataset_500_!G:G,A6,marketing_campaign_dataset_500_!P:P),0) -> 3.0568182
A8: Summary_Statistics
A9: Best_Perf_Channel | B9: =INDEX(A2:A6, MATCH(MAX(C2:C6), C2:C6,0)) -> Instagram
A10: Most_Campaigns | B10: =INDEX(A2:A6, MATCH(MAX(B2:B6),B2:B6,0)) -> Instagram
A11: Lowest_Ad_Spend | B11: =INDEX(A2:A6,MATCH(MIN(D2:D6),D2:D6,0)) -> Email

Sheet Cleaned_data
A1: Campaign_ID | B1: Date | C1: Customer_ID | D1: Age | E1: Gender | F1: Country | G1: Marketing_Channel | H1: Campaign_Type | I1: Ad_Spend | J1: Impressions | K1: Clicks | L1: Conversions | M1: Customer_Satisfaction | N1: CTR_% | O1: Conversion_Rate_% | P1: Cust_satifaction_full | Q1: Col_Q | R1: Col_R | S1: avg_cust_satisfaction | T1: Col_T | U1: Num_over_100 | V1: Perfomance_Rating | W1: CTR_Category | X1: Spend_Flag | Y1: Channel_Benchmark | Z1: Performance_vs_Benchmark | AA1: Campaign_type_flag | AD1: Column_blanks
A2: MKT1000 | B2: 45467 | C2: C378 | D2: 27 | E2: Male | F2: USA | G2: Facebook Ads | H2: Product Launch | I2: 1779.52 | J2: 35715 | K2: 3140 | L2: 274 | M2: 2 | N2: 8.7918242 | O2: 8.7261146 | P2: =IF(ISBLANK(M2), $S$2, M2) -> 2 | S2: =ROUND(AVERAGE(M:M),0) -> 3 | U2: =COUNTIF(N2:N1000, N2>100) -> 0 | V2: =IF(AND(L2>200,K2>3000),"Top Performer", IF(AND(L2>=100,K2>=1000),"Average Performer","Low Performer")) -> Top Performer | W2: {=_xlfn.IFS(N2>=20, "High",N2>=10, "Medium", N2<10, "Low")} -> #NAME? | X2: =IF(I2>1000, "High Budget",IF(I2>=500, "Medium Budget", "Low Budget")) -> High Budget | Y2: =VLOOKUP(G2, Lookup_table!B:C,2,0) -> 0.5 | Z2: =IF(I2/K2<Y2, "Efficient Spend", "Inefficient Spend") -> Inefficient Spend | AA2: =VLOOKUP(H2, Lookup_table!E:F,2,0) -> High | AC2: Duplicate_checker | AD2: Age | AE2: =COUNTBLANK(Cleaned_data!D2:D501) -> 0
A3: MKT1001 | B3: 45488 | C3: C345 | D3: 24 | E3: Female | F3: Nigeria | G3: Google Ads | H3: Brand Awareness | I3: 464.78 | J3: 13758 | K3: 3324 | L3: 5 | M3: 3 | N3: 24.160488 | O3: 0.15042118 | P3: =IF(ISBLANK(M3), $S$2, M3) -> 3 | U3: =COUNTIF(N3:N1001, N3>100) -> 0 | V3: =IF(AND(L3>200,K3>3000),"Top Performer", IF(AND(L3>=100,K3>=1000),"Average Performer","Low Performer")) -> Low Performer | W3: {=_xlfn.IFS(N3>=20, "High",N3>=10, "Medium", N3<10, "Low")} -> #NAME? | X3: =IF(I3>1000, "High Budget",IF(I3>=500, "Medium Budget", "Low Budget")) -> Low Budget | Y3: =VLOOKUP(G3, Lookup_table!B:C,2,0) -> 1.2 | Z3: =IF(I3/K3<Y3, "Efficient Spend", "Inefficient Spend") -> Efficient Spend | AA3: =VLOOKUP(H3, Lookup_table!E:F,2,0) -> Medium | AC3: =COUNTIF($A$2:$A2,A2) -> 1 | AD3: Gender | AE3: =COUNTBLANK(Cleaned_data!E2:E501) -> 0
A4: MKT1002 | B4: 45317 | C4: C239 | D4: 35 | E4: Other | F4: USA | G4: Facebook Ads | H4: Holiday Promo | I4: 561.14 | J4: 48381 | K4: 321 | L4: 163 | N4: 0.6634836 | O4: 50.778816 | P4: =IF(ISBLANK(M4), $S$2, M4) -> 3 | V4: =IF(AND(L4>200,K4>3000),"Top Performer", IF(AND(L4>=100,K4>=1000),"Average Performer","Low Performer")) -> Low Performer | W4: {=_xlfn.IFS(N4>=20, "High",N4>=10, "Medium", N4<10, "Low")} -> #NAME? | X4: =IF(I4>1000, "High Budget",IF(I4>=500, "Medium Budget", "Low Budget")) -> Medium Budget | Y4: =VLOOKUP(G4, Lookup_table!B:C,2,0) -> 0.5 | Z4: =IF(I4/K4<Y4, "Efficient Spend", "Inefficient Spend") -> Inefficient Spend | AA4: =VLOOKUP(H4, Lookup_table!E:F,2,0) -> High | AD4: Conversions | AE4: =COUNTBLANK(Cleaned_data!L2:L501) -> 0
A5: MKT1003 | B5: 45359 | C5: C266 | D5: 20 | E5: Male | F5: Nigeria | G5: Facebook Ads | H5: Brand Awareness | I5: 297.57 | J5: 15697 | K5: 3375 | L5: 280 | M5: 5 | N5: 21.500924 | O5: 8.2962963 | P5: =IF(ISBLANK(M5), $S$2, M5) -> 5 | U5: =COUNTIF(N5:N1000, N5>100) -> 0 | V5: =IF(AND(L5>200,K5>3000),"Top Performer", IF(AND(L5>=100,K5>=1000),"Average Performer","Low Performer")) -> Top Performer | W5: {=_xlfn.IFS(N5>=20, "High",N5>=10, "Medium", N5<10, "Low")} -> #NAME? | X5: =IF(I5>1000, "High Budget",IF(I5>=500, "Medium Budget", "Low Budget")) -> Low Budget | Y5: =VLOOKUP(G5, Lookup_table!B:C,2,0) -> 0.5 | Z5: =IF(I5/K5<Y5, "Efficient Spend", "Inefficient Spend") -> Efficient Spend | AA5: =VLOOKUP(H5, Lookup_table!E:F,2,0) -> Medium | AD5: Customer_Satisfaction | AE5: =COUNTBLANK(Cleaned_data!P2:P501) -> 0
A6: MKT1004 | B6: 45503 | C6: C282 | D6: 32 | E6: Female | F6: UK | G6: Referral | H6: Holiday Promo | I6: 1074.86 | J6: 2245 | K6: 4858 | L6: 373 | M6: 2 | N6: 216.39198 | O6: 7.6780568 | P6: =IF(ISBLANK(M6), $S$2, M6) -> 2 | U6: =COUNTIF(N6:N1001, N6>100) -> 0 | V6: =IF(AND(L6>200,K6>3000),"Top Performer", IF(AND(L6>=100,K6>=1000),"Average Performer","Low Performer")) -> Top Performer | W6: {=_xlfn.IFS(N6>=20, "High",N6>=10, "Medium", N6<10, "Low")} -> #NAME? | X6: =IF(I6>1000, "High Budget",IF(I6>=500, "Medium Budget", "Low Budget")) -> High Budget | Y6: =VLOOKUP(G6, Lookup_table!B:C,2,0) -> 0.3 | Z6: =IF(I6/K6<Y6, "Efficient Spend", "Inefficient Spend") -> Efficient Spend | AA6: =VLOOKUP(H6, Lookup_table!E:F,2,0) -> High
A7: MKT1005 | B7: 45395 | C7: C227 | D7: 64 | E7: Other | F7: Ghana | G7: Instagram | H7: Brand Awareness | I7: 665.19 | J7: 10209 | K7: 2859 | L7: 149 | M7: 5 | N7: 28.004702 | O7: 5.2116125 | P7: =IF(ISBLANK(M7), $S$2, M7) -> 5 | U7: =COUNTIF(N7:N1002, N7>100) -> 0 | V7: =IF(AND(L7>200,K7>3000),"Top Performer", IF(AND(L7>=100,K7>=1000),"Average Performer","Low Performer")) -> Average Performer | W7: {=_xlfn.IFS(N7>=20, "High",N7>=10, "Medium", N7<10, "Low")} -> #NAME? | X7: =IF(I7>1000, "High Budget",IF(I7>=500, "Medium Budget", "Low Budget")) -> Medium Budget | Y7: =VLOOKUP(G7, Lookup_table!B:C,2,0) -> 0.75 | Z7: =IF(I7/K7<Y7, "Efficient Spend", "Inefficient Spend") -> Efficient Spend | AA7: =VLOOKUP(H7, Lookup_table!E:F,2,0) -> Medium
A8: MKT1006 | B8: 45640 | C8: C279 | D8: 20 | E8: Other | F8: UK | G8: Instagram | H8: Holiday Promo | I8: 514.58 | J8: 11892 | K8: 367 | L8: 293 | M8: 4 | N8: 3.0861083 | O8: 79.836512 | P8: =IF(ISBLANK(M8), $S$2, M8) -> 4 | U8: =COUNTIF(N8:N1003, N8>100) -> 0 | V8: =IF(AND(L8>200,K8>3000),"Top Performer", IF(AND(L8>=100,K8>=1000),"Average Performer","Low Performer")) -> Low Performer | W8: {=_xlfn.IFS(N8>=20, "High",N8>=10, "Medium", N8<10, "Low")} -> #NAME? | X8: =IF(I8>1000, "High Budget",IF(I8>=500, "Medium Budget", "Low Budget")) -> Medium Budget | Y8: =VLOOKUP(G8, Lookup_table!B:C,2,0) -> 0.75 | Z8: =IF(I8/K8<Y8, "Efficient Spend", "Inefficient Spend") -> Inefficient Spend | AA8: =VLOOKUP(H8, Lookup_table!E:F,2,0) -> High
A9: MKT1007 | B9: 45477 | C9: C279 | D9: 49 | E9: Other | F9: South Africa | G9: Referral | H9: Holiday Promo | I9: 187.7 | J9: 34575 | K9: 4519 | L9: 6 | M9: 3 | N9: 13.070137 | O9: 0.13277274 | P9: =IF(ISBLANK(M9), $S$2, M9) -> 3 | U9: =COUNTIF(N9:N1004, N9>100) -> 0 | V9: =IF(AND(L9>200,K9>3000),"Top Performer", IF(AND(L9>=100,K9>=1000),"Average Performer","Low Performer")) -> Low Performer | W9: {=_xlfn.IFS(N9>=20, "High",N9>=10, "Medium", N9<10, "Low")} -> #NAME? | X9: =IF(I9>1000, "High Budget",IF(I9>=500, "Medium Budget", "Low Budget")) -> Low Budget | Y9: =VLOOKUP(G9, Lookup_table!B:C,2,0) -> 0.3 | Z9: =IF(I9/K9<Y9, "Efficient Spend", "Inefficient Spend") -> Efficient Spend | AA9: =VLOOKUP(H9, Lookup_table!E:F,2,0) -> High
A10: MKT1008 | B10: 45315 | C10: C338 | D10: 26 | E10: Female | F10: South Africa | G10: Facebook Ads | H10: Product Launch | I10: 1985.97 | J10: 26045 | K10: 2084 | L10: 240 | M10: 4 | N10: 8.0015358 | O10: 11.516315 | P10: =IF(ISBLANK(M10), $S$2, M10) -> 4 | U10: =COUNTIF(N10:N1005, N10>100) -> 0 | V10: =IF(AND(L10>200,K10>3000),"Top Performer", IF(AND(L10>=100,K10>=1000),"Average Performer","Low Performer")) -> Average Performer | W10: {=_xlfn.IFS(N10>=20, "High",N10>=10, "Medium", N10<10, "Low")} -> #NAME? | X10: =IF(I10>1000, "High Budget",IF(I10>=500, "Medium Budget", "Low Budget")) -> High Budget | Y10: =VLOOKUP(G10, Lookup_table!B:C,2,0) -> 0.5 | Z10: =IF(I10/K10<Y10, "Efficient Spend", "Inefficient Spend") -> Inefficient Spend | AA10: =VLOOKUP(H10, Lookup_table!E:F,2,0) -> High
A11: MKT1009 | B11: 45364 | C11: C346 | D11: 31 | E11: Other | F11: Nigeria | G11: Instagram | H11: Brand Awareness | I11: 1642.32 | J11: 8802 | K11: 735 | L11: 220 | M11: 5 | N11: 8.3503749 | O11: 29.931973 | P11: =IF(ISBLANK(M11), $S$2, M11) -> 5 | U11: =COUNTIF(N11:N1006, N11>100) -> 0 | V11: =IF(AND(L11>200,K11>3000),"Top Performer", IF(AND(L11>=100,K11>=1000),"Average Performer","Low Performer")) -> Low Performer | W11: {=_xlfn.IFS(N11>=20, "High",N11>=10, "Medium", N11<10, "Low")} -> #NAME? | X11: =IF(I11>1000, "High Budget",IF(I11>=500, "Medium Budget", "Low Budget")) -> High Budget | Y11: =VLOOKUP(G11, Lookup_table!B:C,2,0) -> 0.75 | Z11: =IF(I11/K11<Y11, "Efficient Spend", "Inefficient Spend") -> Inefficient Spend | AA11: =VLOOKUP(H11, Lookup_table!E:F,2,0) -> Medium
A12: MKT1010 | B12: 45637 | C12: C252 | D12: 46 | E12: Male | F12: Kenya | G12: Referral | H12: Product Launch | I12: 686.5 | J12: 8134 | K12: 1108 | L12: 140 | M12: 1 | N12: 13.621834 | O12: 12.635379 | P12: =IF(ISBLANK(M12), $S$2, M12) -> 1 | U12: =COUNTIF(N12:N1007, N12>100) -> 0 | V12: =IF(AND(L12>200,K12>3000),"Top Performer", IF(AND(L12>=100,K12>=1000),"Average Performer","Low Performer")) -> Average Performer | W12: {=_xlfn.IFS(N12>=20, "High",N12>=10, "Medium", N12<10, "Low")} -> #NAME? | X12: =IF(I12>1000, "High Budget",IF(I12>=500, "Medium Budget", "Low Budget")) -> Medium Budget | Y12: =VLOOKUP(G12, Lookup_table!B:C,2,0) -> 0.3 | Z12: =IF(I12/K12<Y12, "Efficient Spend", "Inefficient Spend") -> Inefficient Spend | AA12: =VLOOKUP(H12, Lookup_table!E:F,2,0) -> High
A13: MKT1011 | B13: 45334 | C13: C334 | D13: 59 | E13: Other | F13: South Africa | G13: Google Ads | H13: Product Launch | I13: 847.08 | J13: 24160 | K13: 4205 | L13: 211 | M13: 5 | N13: 17.404801 | O13: 5.0178359 | P13: =IF(ISBLANK(M13), $S$2, M13) -> 5 | U13: =COUNTIF(N13:N1008, N13>100) -> 0 | V13: =IF(AND(L13>200,K13>3000),"Top Performer", IF(AND(L13>=100,K13>=1000),"Average Performer","Low Performer")) -> Top Performer | W13: {=_xlfn.IFS(N13>=20, "High",N13>=10, "Medium", N13<10, "Low")} -> #NAME? | X13: =IF(I13>1000, "High Budget",IF(I13>=500, "Medium Budget", "Low Budget")) -> Medium Budget | Y13: =VLOOKUP(G13, Lookup_table!B:C,2,0) -> 1.2 | Z13: =IF(I13/K13<Y13, "Efficient Spend", "Inefficient Spend") -> Efficient Spend | AA13: =VLOOKUP(H13, Lookup_table!E:F,2,0) -> High
A14: MKT1012 | B14: 45510 | C14: C345 | D14: 44 | E14: Other | F14: Nigeria | G14: Email | H14: Discount | I14: 1143.36 | J14: 8173 | K14: 825 | L14: 16 | N14: 10.094213 | O14: 1.9393939 | P14: =IF(ISBLANK(M14), $S$2, M14) -> 3 | U14: =COUNTIF(N14:N1009, N14>100) -> 0 | V14: =IF(AND(L14>200,K14>3000),"Top Performer", IF(AND(L14>=100,K14>=1000),"Average Performer","Low Performer")) -> Low Performer | W14: {=_xlfn.IFS(N14>=20, "High",N14>=10, "Medium", N14<10, "Low")} -> #NAME? | X14: =IF(I14>1000, "High Budget",IF(I14>=500, "Medium Budget", "Low Budget")) -> High Budget | Y14: =VLOOKUP(G14, Lookup_table!B:C,2,0) -> 0.2 | Z14: =IF(I14/K14<Y14, "Efficient Spend", "Inefficient Spend") -> Inefficient Spend | AA14: =VLOOKUP(H14, Lookup_table!E:F,2,0) -> Medium
A15: MKT1013 | B15: 45459 | C15: C267 | D15: 57 | E15: Male | F15: South Africa | G15: Facebook Ads | H15: Discount | I15: 151.38 | J15: 11942 | K15: 4640 | L15: 59 | M15: 3 | N15: 38.854463 | O15: 1.2715517 | P15: =IF(ISBLANK(M15), $S$2, M15) -> 3 | V15: =IF(AND(L15>200,K15>3000),"Top Performer", IF(AND(L15>=100,K15>=1000),"Average Performer","Low Performer")) -> Low Performer | W15: {=_xlfn.IFS(N15>=20, "High",N15>=10, "Medium", N15<10, "Low")} -> #NAME? | X15: =IF(I15>1000, "High Budget",IF(I15>=500, "Medium Budget", "Low Budget")) -> Low Budget | Y15: =VLOOKUP(G15, Lookup_table!B:C,2,0) -> 0.5 | Z15: =IF(I15/K15<Y15, "Efficient Spend", "Inefficient Spend") -> Efficient Spend | AA15: =VLOOKUP(H15, Lookup_table!E:F,2,0) -> Medium
A16: MKT1014 | B16: 45360 | C16: C290 | D16: 36 | E16: Female | F16: USA | G16: Facebook Ads | H16: Discount | I16: 782.56 | J16: 9132 | K16: 1618 | L16: 74 | M16: 1 | N16: 17.717915 | O16: 4.5735476 | P16: =IF(ISBLANK(M16), $S$2, M16) -> 1 | V16: =IF(AND(L16>200,K16>3000),"Top Performer", IF(AND(L16>=100,K16>=1000),"Average Performer","Low Performer")) -> Low Performer | W16: {=_xlfn.IFS(N16>=20, "High",N16>=10, "Medium", N16<10, "Low")} -> #NAME? | X16: =IF(I16>1000, "High Budget",IF(I16>=500, "Medium Budget", "Low Budget")) -> Medium Budget | Y16: =VLOOKUP(G16, Lookup_table!B:C,2,0) -> 0.5 | Z16: =IF(I16/K16<Y16, "Efficient Spend", "Inefficient Spend") -> Efficient Spend | AA16: =VLOOKUP(H16, Lookup_table!E:F,2,0) -> Medium
A17: MKT1015 | B17: 45292 | C17: C300 | D17: 38 | E17: Male | F17: Ghana | G17: Instagram | H17: Holiday Promo | I17: 1170.73 | J17: 45111 | K17: 602 | L17: 207 | M17: 1 | N17: 1.334486 | O17: 34.385382 | P17: =IF(ISBLANK(M17), $S$2, M17) -> 1 | V17: =IF(AND(L17>200,K17>3000),"Top Performer", IF(AND(L17>=100,K17>=1000),"Average Performer","Low Performer")) -> Low Performer | W17: {=_xlfn.IFS(N17>=20, "High",N17>=10, "Medium", N17<10, "Low")} -> #NAME? | X17: =IF(I17>1000, "High Budget",IF(I17>=500, "Medium Budget", "Low Budget")) -> High Budget | Y17: =VLOOKUP(G17, Lookup_table!B:C,2,0) -> 0.75 | Z17: =IF(I17/K17<Y17, "Efficient Spend", "Inefficient Spend") -> Inefficient Spend | AA17: =VLOOKUP(H17, Lookup_table!E:F,2,0) -> High
A18: MKT1016 | B18: 45367 | C18: C300 | D18: 41 | E18: Male | F18: Kenya | G18: Referral | H18: Holiday Promo | I18: 1924.46 | J18: 5516 | K18: 4976 | L18: 221 | M18: 5 | N18: 90.210297 | O18: 4.4413183 | P18: =IF(ISBLANK(M18), $S$2, M18) -> 5 | V18: =IF(AND(L18>200,K18>3000),"Top Performer", IF(AND(L18>=100,K18>=1000),"Average Performer","Low Performer")) -> Top Performer | W18: {=_xlfn.IFS(N18>=20, "High",N18>=10, "Medium", N18<10, "Low")} -> #NAME? | X18: =IF(I18>1000, "High Budget",IF(I18>=500, "Medium Budget", "Low Budget")) -> High Budget | Y18: =VLOOKUP(G18, Lookup_table!B:C,2,0) -> 0.3 | Z18: =IF(I18/K18<Y18, "Efficient Spend", "Inefficient Spend") -> Inefficient Spend | AA18: =VLOOKUP(H18, Lookup_table!E:F,2,0) -> High
A19: MKT1017 | B19: 45603 | C19: C210 | D19: 46 | E19: Male | F19: South Africa | G19: Email | H19: Product Launch | I19: 1929.87 | J19: 9198 | K19: 497 | L19: 300 | M19: 5 | N19: 5.4033486 | O19: 60.362173 | P19: =IF(ISBLANK(M19), $S$2, M19) -> 5 | V19: =IF(AND(L19>200,K19>3000),"Top Performer", IF(AND(L19>=100,K19>=1000),"Average Performer","Low Performer")) -> Low Performer | W19: {=_xlfn.IFS(N19>=20, "High",N19>=10, "Medium", N19<10, "Low")} -> #NAME? | X19: =IF(I19>1000, "High Budget",IF(I19>=500, "Medium Budget", "Low Budget")) -> High Budget | Y19: =VLOOKUP(G19, Lookup_table!B:C,2,0) -> 0.2 | Z19: =IF(I19/K19<Y19, "Efficient Spend", "Inefficient Spend") -> Inefficient Spend | AA19: =VLOOKUP(H19, Lookup_table!E:F,2,0) -> High
A20: MKT1018 | B20: 45542 | C20: C211 | D20: 46 | E20: Female | F20: Kenya | G20: Email | H20: Brand Awareness | I20: 1527.84 | J20: 13127 | K20: 4960 | L20: 351 | M20: 5 | N20: 37.784719 | O20: 7.0766129 | P20: =IF(ISBLANK(M20), $S$2, M20) -> 5 | V20: =IF(AND(L20>200,K20>3000),"Top Performer", IF(AND(L20>=100,K20>=1000),"Average Performer","Low Performer")) -> Top Performer | W20: {=_xlfn.IFS(N20>=20, "High",N20>=10, "Medium", N20<10, "Low")} -> #NAME? | X20: =IF(I20>1000, "High Budget",IF(I20>=500, "Medium Budget", "Low Budget")) -> High Budget | Y20: =VLOOKUP(G20, Lookup_table!B:C,2,0) -> 0.2 | Z20: =IF(I20/K20<Y20, "Efficient Spend", "Inefficient Spend") -> Inefficient Spend | AA20: =VLOOKUP(H20, Lookup_table!E:F,2,0) -> Medium
A21: MKT1019 | B21: 45298 | C21: C341 | D21: 33 | E21: Female | F21: South Africa | G21: Email | H21: Brand Awareness | I21: 149.18 | J21: 33722 | K21: 3046 | L21: 323 | M21: 4 | N21: 9.032679 | O21: 10.604071 | P21: =IF(ISBLANK(M21), $S$2, M21) -> 4 | V21: =IF(AND(L21>200,K21>3000),"Top Performer", IF(AND(L21>=100,K21>=1000),"Average Performer","Low Performer")) -> Top Performer | W21: {=_xlfn.IFS(N21>=20, "High",N21>=10, "Medium", N21<10, "Low")} -> #NAME? | X21: =IF(I21>1000, "High Budget",IF(I21>=500, "Medium Budget", "Low Budget")) -> Low Budget | Y21: =VLOOKUP(G21, Lookup_table!B:C,2,0) -> 0.2 | Z21: =IF(I21/K21<Y21, "Efficient Spend", "Inefficient Spend") -> Efficient Spend | AA21: =VLOOKUP(H21, Lookup_table!E:F,2,0) -> Medium
A22: MKT1020 | B22: 45567 | C22: C359 | D22: 63 | E22: Other | F22: Kenya | G22: Instagram | H22: Holiday Promo | I22: 1226.99 | J22: 5271 | K22: 717 | L22: 289 | M22: 4 | N22: 13.602732 | O22: 40.306834 | P22: =IF(ISBLANK(M22), $S$2, M22) -> 4 | V22: =IF(AND(L22>200,K22>3000),"Top Performer", IF(AND(L22>=100,K22>=1000),"Average Performer","Low Performer")) -> Low Performer | W22: {=_xlfn.IFS(N22>=20, "High",N22>=10, "Medium", N22<10, "Low")} -> #NAME? | X22: =IF(I22>1000, "High Budget",IF(I22>=500, "Medium Budget", "Low Budget")) -> High Budget | Y22: =VLOOKUP(G22, Lookup_table!B:C,2,0) -> 0.75 | Z22: =IF(I22/K22<Y22, "Efficient Spend", "Inefficient Spend") -> Inefficient Spend | AA22: =VLOOKUP(H22, Lookup_table!E:F,2,0) -> High
A23: MKT1021 | B23: 45336 | C23: C298 | D23: 51 | E23: Female | F23: Ghana | G23: Google Ads | H23: Brand Awareness | I23: 948.77 | J23: 11269 | K23: 1703 | L23: 321 | M23: 2 | N23: 15.112255 | O23: 18.84909 | P23: =IF(ISBLANK(M23), $S$2, M23) -> 2 | V23: =IF(AND(L23>200,K23>3000),"Top Performer", IF(AND(L23>=100,K23>=1000),"Average Performer","Low Performer")) -> Average Performer | W23: {=_xlfn.IFS(N23>=20, "High",N23>=10, "Medium", N23<10, "Low")} -> #NAME? | X23: =IF(I23>1000, "High Budget",IF(I23>=500, "Medium Budget", "Low Budget")) -> Medium Budget | Y23: =VLOOKUP(G23, Lookup_table!B:C,2,0) -> 1.2 | Z23: =IF(I23/K23<Y23, "Efficient Spend", "Inefficient Spend") -> Efficient Spend | AA23: =VLOOKUP(H23, Lookup_table!E:F,2,0) -> Medium
A24: MKT1022 | B24: 45483 | C24: C367 | D24: 18 | E24: Female | F24: UK | G24: Email | H24: Discount | I24: 1314.42 | J24: 46761 | K24: 3166 | L24: 267 | M24: 4 | N24: 6.7705994 | O24: 8.4333544 | P24: =IF(ISBLANK(M24), $S$2, M24) -> 4 | V24: =IF(AND(L24>200,K24>3000),"Top Performer", IF(AND(L24>=100,K24>=1000),"Average Performer","Low Performer")) -> Top Performer | W24: {=_xlfn.IFS(N24>=20, "High",N24>=10, "Medium", N24<10, "Low")} -> #NAME? | X24: =IF(I24>1000, "High Budget",IF(I24>=500, "Medium Budget", "Low Budget")) -> High Budget | Y24: =VLOOKUP(G24, Lookup_table!B:C,2,0) -> 0.2 | Z24: =IF(I24/K24<Y24, "Efficient Spend", "Inefficient Spend") -> Inefficient Spend | AA24: =VLOOKUP(H24, Lookup_table!E:F,2,0) -> Medium
A25: MKT1023 | B25: 45617 | C25: C363 | D25: 19 | E25: Male | F25: South Africa | G25: Google Ads | H25: Discount | I25: 820.68 | J25: 31180 | K25: 3849 | L25: 261 | M25: 3 | N25: 12.344452 | O25: 6.7809821 | P25: =IF(ISBLANK(M25), $S$2, M25) -> 3 | V25: =IF(AND(L25>200,K25>3000),"Top Performer", IF(AND(L25>=100,K25>=1000),"Average Performer","Low Performer")) -> Top Performer | W25: {=_xlfn.IFS(N25>=20, "High",N25>=10, "Medium", N25<10, "Low")} -> #NAME? | X25: =IF(I25>1000, "High Budget",IF(I25>=500, "Medium Budget", "Low Budget")) -> Medium Budget | Y25: =VLOOKUP(G25, Lookup_table!B:C,2,0) -> 1.2 | Z25: =IF(I25/K25<Y25, "Efficient Spend", "Inefficient Spend") -> Efficient Spend | AA25: =VLOOKUP(H25, Lookup_table!E:F,2,0) -> Medium
A26: MKT1024 | B26: 45604 | C26: C224 | D26: 42 | E26: Other | F26: UK | G26: Referral | H26: Discount | I26: 1019.29 | J26: 11855 | K26: 482 | L26: 113 | N26: 4.065795 | O26: 23.443983 | P26: =IF(ISBLANK(M26), $S$2, M26) -> 3 | V26: =IF(AND(L26>200,K26>3000),"Top Performer", IF(AND(L26>=100,K26>=1000),"Average Performer","Low Performer")) -> Low Performer | W26: {=_xlfn.IFS(N26>=20, "High",N26>=10, "Medium", N26<10, "Low")} -> #NAME? | X26: =IF(I26>1000, "High Budget",IF(I26>=500, "Medium Budget", "Low Budget")) -> High Budget | Y26: =VLOOKUP(G26, Lookup_table!B:C,2,0) -> 0.3 | Z26: =IF(I26/K26<Y26, "Efficient Spend", "Inefficient Spend") -> Inefficient Spend | AA26: =VLOOKUP(H26, Lookup_table!E:F,2,0) -> Medium
A27: MKT1025 | B27: 45444 | C27: C338 | D27: 57 | E27: Female | F27: Ghana | G27: Instagram | H27: Holiday Promo | I27: 921.21 | J27: 33409 | K27: 3245 | L27: 6 | N27: 9.7129516 | O27: 0.18489985 | P27: =IF(ISBLANK(M27), $S$2, M27) -> 3 | V27: =IF(AND(L27>200,K27>3000),"Top Performer", IF(AND(L27>=100,K27>=1000),"Average Performer","Low Performer")) -> Low Performer | W27: {=_xlfn.IFS(N27>=20, "High",N27>=10, "Medium", N27<10, "Low")} -> #NAME? | X27: =IF(I27>1000, "High Budget",IF(I27>=500, "Medium Budget", "Low Budget")) -> Medium Budget | Y27: =VLOOKUP(G27, Lookup_table!B:C,2,0) -> 0.75 | Z27: =IF(I27/K27<Y27, "Efficient Spend", "Inefficient Spend") -> Efficient Spend | AA27: =VLOOKUP(H27, Lookup_table!E:F,2,0) -> High
A28: MKT1026 | B28: 45475 | C28: C280 | D28: 54 | E28: Male | F28: Kenya | G28: Instagram | H28: Holiday Promo | I28: 312.38 | J28: 5193 | K28: 2334 | L28: 253 | M28: 2 | N28: 44.945118 | O28: 10.83976 | P28: =IF(ISBLANK(M28), $S$2, M28) -> 2 | V28: =IF(AND(L28>200,K28>3000),"Top Performer", IF(AND(L28>=100,K28>=1000),"Average Performer","Low Performer")) -> Average Performer | W28: {=_xlfn.IFS(N28>=20, "High",N28>=10, "Medium", N28<10, "Low")} -> #NAME? | X28: =IF(I28>1000, "High Budget",IF(I28>=500, "Medium Budget", "Low Budget")) -> Low Budget | Y28: =VLOOKUP(G28, Lookup_table!B:C,2,0) -> 0.75 | Z28: =IF(I28/K28<Y28, "Efficient Spend", "Inefficient Spend") -> Efficient Spend | AA28: =VLOOKUP(H28, Lookup_table!E:F,2,0) -> High
A29: MKT1027 | B29: 45404 | C29: C246 | D29: 41 | E29: Female | G29: Google Ads | H29: Discount | I29: 1461.16 | J29: 29339 | K29: 2849 | L29: 67 | N29: 9.7106241 | O29: 2.3517024 | P29: =IF(ISBLANK(M29), $S$2, M29) -> 3 | V29: =IF(AND(L29>200,K29>3000),"Top Performer", IF(AND(L29>=100,K29>=1000),"Average Performer","Low Performer")) -> Low Performer | W29: {=_xlfn.IFS(N29>=20, "High",N29>=10, "Medium", N29<10, "Low")} -> #NAME? | X29: =IF(I29>1000, "High Budget",IF(I29>=500, "Medium Budget", "Low Budget")) -> High Budget | Y29: =VLOOKUP(G29, Lookup_table!B:C,2,0) -> 1.2 | Z29: =IF(I29/K29<Y29, "Efficient Spend", "Inefficient Spend") -> Efficient Spend | AA29: =VLOOKUP(H29, Lookup_table!E:F,2,0) -> Medium
A30: MKT1028 | B30: 45543 | C30: C350 | D30: 40 | E30: Female | F30: USA | G30: Google Ads | H30: Discount | I30: 64.23 | J30: 14536 | K30: 2927 | L30: 375 | N30: 20.136214 | O30: 12.811753 | P30: =IF(ISBLANK(M30), $S$2, M30) -> 3 | V30: =IF(AND(L30>200,K30>3000),"Top Performer", IF(AND(L30>=100,K30>=1000),"Average Performer","Low Performer")) -> Average Performer | W30: {=_xlfn.IFS(N30>=20, "High",N30>=10, "Medium", N30<10, "Low")} -> #NAME? | X30: =IF(I30>1000, "High Budget",IF(I30>=500, "Medium Budget", "Low Budget")) -> Low Budget | Y30: =VLOOKUP(G30, Lookup_table!B:C,2,0) -> 1.2 | Z30: =IF(I30/K30<Y30, "Efficient Spend", "Inefficient Spend") -> Efficient Spend | AA30: =VLOOKUP(H30, Lookup_table!E:F,2,0) -> Medium
A31: MKT1029 | B31: 45481 | C31: C363 | D31: 61 | E31: Male | F31: USA | G31: Instagram | H31: Holiday Promo | I31: 987.76 | J31: 1245 | K31: 4323 | L31: 119 | M31: 5 | N31: 347.22892 | O31: 2.752718 | P31: =IF(ISBLANK(M31), $S$2, M31) -> 5 | U31: =COUNTIF(N27:N1000, N31>100) -> 0 | V31: =IF(AND(L31>200,K31>3000),"Top Performer", IF(AND(L31>=100,K31>=1000),"Average Performer","Low Performer")) -> Average Performer | W31: {=_xlfn.IFS(N31>=20, "High",N31>=10, "Medium", N31<10, "Low")} -> #NAME? | X31: =IF(I31>1000, "High Budget",IF(I31>=500, "Medium Budget", "Low Budget")) -> Medium Budget | Y31: =VLOOKUP(G31, Lookup_table!B:C,2,0) -> 0.75 | Z31: =IF(I31/K31<Y31, "Efficient Spend", "Inefficient Spend") -> Efficient Spend | AA31: =VLOOKUP(H31, Lookup_table!E:F,2,0) -> High
A32: MKT1030 | B32: 45582 | C32: C313 | D32: 19 | E32: Male | F32: Kenya | G32: Referral | H32: Product Launch | I32: 1670.14 | J32: 47856 | K32: 3265 | L32: 392 | M32: 3 | N32: 6.822551 | O32: 12.006126 | P32: =IF(ISBLANK(M32), $S$2, M32) -> 3 | V32: =IF(AND(L32>200,K32>3000),"Top Performer", IF(AND(L32>=100,K32>=1000),"Average Performer","Low Performer")) -> Top Performer | W32: {=_xlfn.IFS(N32>=20, "High",N32>=10, "Medium", N32<10, "Low")} -> #NAME? | X32: =IF(I32>1000, "High Budget",IF(I32>=500, "Medium Budget", "Low Budget")) -> High Budget | Y32: =VLOOKUP(G32, Lookup_table!B:C,2,0) -> 0.3 | Z32: =IF(I32/K32<Y32, "Efficient Spend", "Inefficient Spend") -> Inefficient Spend | AA32: =VLOOKUP(H32, Lookup_table!E:F,2,0) -> High
A33: MKT1031 | B33: 45604 | C33: C207 | D33: 38 | E33: Male | F33: South Africa | G33: Facebook Ads | H33: Product Launch | I33: 1582.87 | J33: 18161 | K33: 3759 | L33: 384 | M33: 2 | N33: 20.698199 | O33: 10.215483 | P33: =IF(ISBLANK(M33), $S$2, M33) -> 2 | V33: =IF(AND(L33>200,K33>3000),"Top Performer", IF(AND(L33>=100,K33>=1000),"Average Performer","Low Performer")) -> Top Performer | W33: {=_xlfn.IFS(N33>=20, "High",N33>=10, "Medium", N33<10, "Low")} -> #NAME? | X33: =IF(I33>1000, "High Budget",IF(I33>=500, "Medium Budget", "Low Budget")) -> High Budget | Y33: =VLOOKUP(G33, Lookup_table!B:C,2,0) -> 0.5 | Z33: =IF(I33/K33<Y33, "Efficient Spend", "Inefficient Spend") -> Efficient Spend | AA33: =VLOOKUP(H33, Lookup_table!E:F,2,0) -> High
A34: MKT1032 | B34: 45493 | C34: C246 | D34: 26 | E34: Other | F34: USA | G34: Facebook Ads | H34: Holiday Promo | I34: 688.82 | J34: 44318 | K34: 2759 | L34: 389 | M34: 3 | N34: 6.2254614 | O34: 14.099311 | P34: =IF(ISBLANK(M34), $S$2, M34) -> 3 | V34: =IF(AND(L34>200,K34>3000),"Top Performer", IF(AND(L34>=100,K34>=1000),"Average Performer","Low Performer")) -> Average Performer | W34: {=_xlfn.IFS(N34>=20, "High",N34>=10, "Medium", N34<10, "Low")} -> #NAME? | X34: =IF(I34>1000, "High Budget",IF(I34>=500, "Medium Budget", "Low Budget")) -> Medium Budget | Y34: =VLOOKUP(G34, Lookup_table!B:C,2,0) -> 0.5 | Z34: =IF(I34/K34<Y34, "Efficient Spend", "Inefficient Spend") -> Efficient Spend | AA34: =VLOOKUP(H34, Lookup_table!E:F,2,0) -> High
A35: MKT1033 | B35: 45330 | C35: C255 | D35: 41 | E35: Other | F35: Ghana | G35: Email | H35: Holiday Promo | I35: 1079.14 | J35: 48566 | K35: 610 | L35: 85 | N35: 1.2560227 | O35: 13.934426 | P35: =IF(ISBLANK(M35), $S$2, M35) -> 3 | V35: =IF(AND(L35>200,K35>3000),"Top Performer", IF(AND(L35>=100,K35>=1000),"Average Performer","Low Performer")) -> Low Performer | W35: {=_xlfn.IFS(N35>=20, "High",N35>=10, "Medium", N35<10, "Low")} -> #NAME? | X35: =IF(I35>1000, "High Budget",IF(I35>=500, "Medium Budget", "Low Budget")) -> High Budget | Y35: =VLOOKUP(G35, Lookup_table!B:C,2,0) -> 0.2 | Z35: =IF(I35/K35<Y35, "Efficient Spend", "Inefficient Spend") -> Inefficient Spend | AA35: =VLOOKUP(H35, Lookup_table!E:F,2,0) -> High
